Workbook

Sheet Read Me
B2: Learning Program Operations Tracker
B3: Excel-based simulation of a Learning Operations workflow
B5: Purpose
B6: A self-directed practice project simulating the operational side of a Learning Operations role: participant registration, scheduling, attendance monitoring, completion tracking, exception identification, and action follow-up, ending in a management-level KPI dashboard.
B9: Synthetic Data Disclaimer
B10: All 200 participant records, names, courses, batches, trainers, and feedback scores in this workbook are synthetically generated for demonstration purposes. They do not represent real individuals, a real training program, or real Learning Management System (LMS) data.
B13: Workbook Structure
B14: • Learning Operations Dashboard — Management-level KPIs: participants, attendance, completion, feedback, open actions, and course performance at a glance.
B15: • Raw Data — 200 synthetic participant records: registration status, course, batch, trainer, session date, attendance, completion status, feedback score, pending action.
B16: • Registration Tracker — Registration status breakdown by course, and by course + batch, using COUNTIFS-driven reporting.
B17: • Course Schedule — Course x batch schedule with trainer, session date, registered count, capacity, and seats available.
B18: • Attendance Tracker — Attendance rates by course using COUNTIFS-driven reporting, with an Attendance Health flag.
... B40: Note: All participant records, dates, and operational activities are synthetic and created solely for learning and portfolio demonstration purposes.

Sheet Learning Operations Dashboard
A1: LEARNING OPERATIONS DASHBOARD
A2: Self-directed simulation using synthetic data — Learning Program Operations Tracker
A4: Total Participants | C4: Registered | E4: Attendance Rate
A5: =COUNTA('Raw Data'!$A$2:$A$201) -> 200 | C5: =COUNTIF('Raw Data'!$C$2:$C$201,"Registered") -> 158 | E5: =IFERROR(COUNTIF('Raw Data'!$H$2:$H$201,"Present")/C5,0) -> 0.84177215
A7: Completion Rate | C7: Avg Feedback (out of 5) | E7: Open Actions
A8: =IFERROR(COUNTIF('Raw Data'!$I$2:$I$201,"Completed")/C5,0) -> 0.62025316 | C8: =IFERROR(AVERAGEIF('Raw Data'!$I$2:$I$201,"Completed",'Raw Data'!$J$2:$J$201),0) -> 4.1530612 | E8: =COUNTIF('Exception & Action Tracker'!$K$5:$K$105,"Open") -> 101
A11: Course Performance
A12: Course | B12: Registration Rate | C12: Attendance Rate | D12: Completion Rate | E12: Avg Feedback
A13: Excel Fundamentals | B13: ='Registration Tracker'!F4 -> 0.6875 | C13: ='Attendance Tracker'!E4 -> 0.90909091 | D13: ='Completion Dashboard'!F4 -> 0.81818182 | E13: ='Completion Dashboard'!G4 -> 4.0555556
A14: Data Analytics Basics | B14: ='Registration Tracker'!F5 -> 0.85 | C14: ='Attendance Tracker'!E5 -> 0.94117647 | D14: ='Completion Dashboard'!F5 -> 0.64705882 | E14: ='Completion Dashboard'!G5 -> 3.9545455
A15: Communication Skills | B15: ='Registration Tracker'!F6 -> 0.82608696 | C15: ='Attendance Tracker'!E6 -> 0.78947368 | D15: ='Completion Dashboard'!F6 -> 0.52631579 | E15: ='Completion Dashboard'!G6 -> 4.2
A16: Project Management 101 | B16: ='Registration Tracker'!F7 -> 0.78947368 | C16: ='Attendance Tracker'!E7 -> 0.8 | D16: ='Completion Dashboard'!F7 -> 0.56666667 | E16: ='Completion Dashboard'!G7 -> 4.2352941
A17: SQL for Beginners | B17: ='Registration Tracker'!F8 -> 0.70967742 | C17: ='Attendance Tracker'!E8 -> 0.81818182 | D17: ='Completion Dashboard'!F8 -> 0.54545455 | E17: ='Completion Dashboard'!G8 -> 4.5833333
A18: Leadership Essentials | B18: ='Registration Tracker'!F9 -> 0.86111111 | C18: ='Attendance Tracker'!E9 -> 0.77419355 | D18: ='Completion Dashboard'!F9 -> 0.61290323 | E18: ='Completion Dashboard'!G9 -> 4.1052632
A21: Operational Alerts
A22: ="🔴 Open Pending Actions: "&E8 -> 🔴 Open Pending Actions: 101
A23: ="🟠 Courses Needing Attendance Follow-up: "&COUNTIF('Attendance Tracker'!$G$4:$G$9,"<>Healthy") -> 🟠 Courses Needing Attendance Follow-up: 4
A24: ="🟡 Waitlisted Participants: "&COUNTIF('Raw Data'!$C$2:$C$201,"Waitlisted") -> 🟡 Waitlisted Participants: 26
A25: ="🔴 Dropped Participants: "&COUNTIF('Raw Data'!$I$2:$I$201,"Dropped") -> 🔴 Dropped Participants: 16

Sheet Raw Data
A1: Participant ID | B1: Participant Name | C1: Registration Status | D1: Course | E1: Batch | F1: Trainer | G1: Session Date | H1: Attendance | I1: Completion Status | J1: Feedback Score | K1: Pending Action | L1: Exception Rank
A2: P001 | B2: Reyansh Gupta | C2: Registered | D2: SQL for Beginners | E2: C | F2: Sneha Kulkarni | G2: 46200 | H2: Present | I2: Completed | J2: 5 | L2: =IF(K2="","",COUNTIF($K$2:K2,"<>"))
A3: P002 | B3: Aadhya Shetty | C3: Cancelled | D3: SQL for Beginners | E3: B | F3: Sneha Kulkarni | G3: 46197 | L3: =IF(K3="","",COUNTIF($K$2:K3,"<>"))
A4: P003 | B4: Ishaan Rana | C4: Registered | D4: Communication Skills | E4: A | F4: Kavya Reddy | G4: 46170 | H4: Present | I4: In Progress | K4: Collect interim feedback | L4: =IF(K4="","",COUNTIF($K$2:K4,"<>")) -> 1
A5: P004 | B5: Suman Gupta | C5: Cancelled | D5: Communication Skills | E5: D | F5: Kavya Reddy | G5: 46179 | L5: =IF(K5="","",COUNTIF($K$2:K5,"<>"))
A6: P005 | B6: Deepak Joshi | C6: Registered | D6: Data Analytics Basics | E6: D | F6: Arjun Mehta | G6: 46167 | H6: Present | I6: In Progress | K6: Collect interim feedback | L6: =IF(K6="","",COUNTIF($K$2:K6,"<>")) -> 2
A7: P006 | B7: Sandeep Chawla | C7: Registered | D7: Data Analytics Basics | E7: B | F7: Arjun Mehta | G7: 46161 | H7: Present | I7: Dropped | K7: Follow up - dropped participant | L7: =IF(K7="","",COUNTIF($K$2:K7,"<>")) -> 3
A8: P007 | B8: Anil Joshi | C8: Registered | D8: SQL for Beginners | E8: B | F8: Sneha Kulkarni | G8: 46197 | H8: Present | I8: Completed | J8: 5 | K8: Send completion certificate | L8: =IF(K8="","",COUNTIF($K$2:K8,"<>")) -> 4
A9: P008 | B9: Radha Banerjee | C9: Registered | D9: SQL for Beginners | E9: D | F9: Sneha Kulkarni | G9: 46203 | H9: Present | I9: Completed | J9: 5 | L9: =IF(K9="","",COUNTIF($K$2:K9,"<>"))
A10: P009 | B10: Aarav Mukherjee | C10: Registered | D10: SQL for Beginners | E10: A | F10: Sneha Kulkarni | G10: 46194 | H10: Present | I10: Completed | J10: 5 | L10: =IF(K10="","",COUNTIF($K$2:K10,"<>"))
A11: P010 | B11: Kiara Rana | C11: Registered | D11: SQL for Beginners | E11: B | F11: Sneha Kulkarni | G11: 46197 | H11: Present | I11: Completed | J11: 5 | L11: =IF(K11="","",COUNTIF($K$2:K11,"<>"))
A12: P011 | B12: Reyansh Nayar | C12: Registered | D12: Leadership Essentials | E12: B | F12: Vikram Rao | G12: 46209 | H12: Absent | K12: Follow up on absence | L12: =IF(K12="","",COUNTIF($K$2:K12,"<>")) -> 5
A13: P012 | B13: Anika Iyer | C13: Waitlisted | D13: Data Analytics Basics | E13: A | F13: Arjun Mehta | G13: 46158 | K13: Resolve waitlist | L13: =IF(K13="","",COUNTIF($K$2:K13,"<>")) -> 6
A14: P013 | B14: Gaurav Bhat | C14: Registered | D14: Excel Fundamentals | E14: D | F14: Priya Nair | G14: 46155 | H14: Present | I14: Dropped | K14: Follow up - dropped participant | L14: =IF(K14="","",COUNTIF($K$2:K14,"<>")) -> 7
A15: P014 | B15: Riya Joshi | C15: Registered | D15: Data Analytics Basics | E15: A | F15: Arjun Mehta | G15: 46158 | H15: Present | I15: Completed | J15: 4 | L15: =IF(K15="","",COUNTIF($K$2:K15,"<>"))
A16: P015 | B16: Aadhya Das | C16: Waitlisted | D16: SQL for Beginners | E16: D | F16: Sneha Kulkarni | G16: 46203 | K16: Resolve waitlist | L16: =IF(K16="","",COUNTIF($K$2:K16,"<>")) -> 8
A17: P016 | B17: Aadhya Mukherjee | C17: Waitlisted | D17: Communication Skills | E17: C | F17: Kavya Reddy | G17: 46176 | K17: Resolve waitlist | L17: =IF(K17="","",COUNTIF($K$2:K17,"<>")) -> 9
A18: P017 | B18: Anita Mehta | C18: Registered | D18: Leadership Essentials | E18: A | F18: Vikram Rao | G18: 46206 | H18: Present | I18: Completed | J18: 5 | L18: =IF(K18="","",COUNTIF($K$2:K18,"<>"))
A19: P018 | B19: Neha Mehta | C19: Registered | D19: SQL for Beginners | E19: A | F19: Sneha Kulkarni | G19: 46194 | H19: Present | I19: Dropped | K19: Follow up - dropped participant | L19: =IF(K19="","",COUNTIF($K$2:K19,"<>")) -> 10
A20: P019 | B20: Sai Banerjee | C20: Registered | D20: Excel Fundamentals | E20: B | F20: Priya Nair | G20: 46149 | H20: Present | I20: Completed | J20: 4 | L20: =IF(K20="","",COUNTIF($K$2:K20,"<>"))
A21: P020 | B21: Geeta Mehta | C21: Registered | D21: Project Management 101 | E21: B | F21: Rohan Iyer | G21: 46185 | H21: Present | I21: Completed | J21: 5 | L21: =IF(K21="","",COUNTIF($K$2:K21,"<>"))
A22: P021 | B22: Aarav Patel | C22: Waitlisted | D22: Excel Fundamentals | E22: B | F22: Priya Nair | G22: 46149 | K22: Resolve waitlist | L22: =IF(K22="","",COUNTIF($K$2:K22,"<>")) -> 11
A23: P022 | B23: Amit Mehta | C23: Registered | D23: Data Analytics Basics | E23: A | F23: Arjun Mehta | G23: 46158 | H23: Present | I23: Completed | J23: 4 | K23: Send completion certificate | L23: =IF(K23="","",COUNTIF($K$2:K23,"<>")) -> 12
A24: P023 | B24: Gaurav Pillai | C24: Registered | D24: Data Analytics Basics | E24: B | F24: Arjun Mehta | G24: 46161 | H24: Present | I24: Completed | J24: 4 | L24: =IF(K24="","",COUNTIF($K$2:K24,"<>"))
A25: P024 | B25: Anil Menon | C25: Registered | D25: SQL for Beginners | E25: B | F25: Sneha Kulkarni | G25: 46197 | H25: Present | I25: Dropped | K25: Follow up - dropped participant | L25: =IF(K25="","",COUNTIF($K$2:K25,"<>")) -> 13
A26: P025 | B26: Aarav Iyer | C26: Cancelled | D26: SQL for Beginners | E26: B | F26: Sneha Kulkarni | G26: 46197 | L26: =IF(K26="","",COUNTIF($K$2:K26,"<>"))
A27: P026 | B27: Suman Das | C27: Waitlisted | D27: Excel Fundamentals | E27: C | F27: Priya Nair | G27: 46152 | K27: Resolve waitlist | L27: =IF(K27="","",COUNTIF($K$2:K27,"<>")) -> 14
A28: P027 | B28: Kavya Verma | C28: Registered | D28: Data Analytics Basics | E28: A | F28: Arjun Mehta | G28: 46158 | H28: Present | I28: Completed | J28: 3 | L28: =IF(K28="","",COUNTIF($K$2:K28,"<>"))
A29: P028 | B29: Shreya Bhat | C29: Registered | D29: Communication Skills | E29: D | F29: Kavya Reddy | G29: 46179 | H29: Present | I29: In Progress | K29: Collect interim feedback | L29: =IF(K29="","",COUNTIF($K$2:K29,"<>")) -> 15
A30: P029 | B30: Naveen Nair | C30: Registered | D30: Data Analytics Basics | E30: A | F30: Arjun Mehta | G30: 46158 | H30: Present | I30: Completed | J30: 3 | L30: =IF(K30="","",COUNTIF($K$2:K30,"<>"))
A31: P030 | B31: Kiara Singh | C31: Cancelled | D31: Excel Fundamentals | E31: B | F31: Priya Nair | G31: 46149 | L31: =IF(K31="","",COUNTIF($K$2:K31,"<>"))
A32: P031 | B32: Usha Singh | C32: Registered | D32: Excel Fundamentals | E32: B | F32: Priya Nair | G32: 46149 | H32: Present | I32: Completed | J32: 4 | L32: =IF(K32="","",COUNTIF($K$2:K32,"<>"))
A33: P032 | B33: Ajay Kulkarni | C33: Registered | D33: Data Analytics Basics | E33: C | F33: Arjun Mehta | G33: 46164 | H33: Present | I33: Dropped | K33: Follow up - dropped participant | L33: =IF(K33="","",COUNTIF($K$2:K33,"<>")) -> 16
A34: P033 | B34: Reyansh Singh | C34: Registered | D34: Leadership Essentials | E34: B | F34: Vikram Rao | G34: 46209 | H34: Present | I34: Completed | J34: 5 | L34: =IF(K34="","",COUNTIF($K$2:K34,"<>"))
A35: P034 | B35: Suman Bose | C35: Registered | D35: SQL for Beginners | E35: B | F35: Sneha Kulkarni | G35: 46197 | H35: Present | I35: Completed | J35: 3 | L35: =IF(K35="","",COUNTIF($K$2:K35,"<>"))
A36: P035 | B36: Swati Ghosh | C36: Registered | D36: Project Management 101 | E36: B | F36: Rohan Iyer | G36: 46185 | H36: Absent | K36: Follow up on absence | L36: =IF(K36="","",COUNTIF($K$2:K36,"<>")) -> 17
A37: P036 | B37: Jyoti Rana | C37: Registered | D37: Data Analytics Basics | E37: A | F37: Arjun Mehta | G37: 46158 | H37: Present | I37: Completed | J37: 5 | K37: Send completion certificate | L37: =IF(K37="","",COUNTIF($K$2:K37,"<>")) -> 18
A38: P037 | B38: Rekha Reddy | C38: Registered | D38: Data Analytics Basics | E38: D | F38: Arjun Mehta | G38: 46167 | H38: Present | I38: Completed | J38: 3 | L38: =IF(K38="","",COUNTIF($K$2:K38,"<>"))
A39: P038 | B39: Suman Menon | C39: Cancelled | D39: Data Analytics Basics | E39: B | F39: Arjun Mehta | G39: 46161 | L39: =IF(K39="","",COUNTIF($K$2:K39,"<>"))
A40: P039 | B40: Diya Ghosh | C40: Registered | D40: Excel Fundamentals | E40: A | F40: Priya Nair | G40: 46146 | H40: Present | I40: Completed | J40: 3 | L40: =IF(K40="","",COUNTIF($K$2:K40,"<>"))
...

Sheet Registration Tracker
A1: Registration Tracker — by Course
A3: Course | B3: Registered | C3: Waitlisted | D3: Cancelled | E3: Total | F3: Registration Rate | G3: Waitlist Rate | H3: Registration Health
A4: Excel Fundamentals | B4: =COUNTIFS('Raw Data'!$D$2:$D$201,$A4,'Raw Data'!$C$2:$C$201,"Registered") -> 22 | C4: =COUNTIFS('Raw Data'!$D$2:$D$201,$A4,'Raw Data'!$C$2:$C$201,"Waitlisted") -> 7 | D4: =COUNTIFS('Raw Data'!$D$2:$D$201,$A4,'Raw Data'!$C$2:$C$201,"Cancelled") -> 3 | E4: =SUM(B4:D4) -> 32 | F4: =IFERROR(B4/E4,0) -> 0.6875 | G4: =IFERROR(C4/E4,0) -> 0.21875 | H4: =IF(F4>=80%,"Healthy",IF(F4>=60%,"Monitor","Action Required")) -> Monitor
A5: Data Analytics Basics | B5: =COUNTIFS('Raw Data'!$D$2:$D$201,$A5,'Raw Data'!$C$2:$C$201,"Registered") -> 34 | C5: =COUNTIFS('Raw Data'!$D$2:$D$201,$A5,'Raw Data'!$C$2:$C$201,"Waitlisted") -> 4 | D5: =COUNTIFS('Raw Data'!$D$2:$D$201,$A5,'Raw Data'!$C$2:$C$201,"Cancelled") -> 2 | E5: =SUM(B5:D5) -> 40 | F5: =IFERROR(B5/E5,0) -> 0.85 | G5: =IFERROR(C5/E5,0) -> 0.1 | H5: =IF(F5>=80%,"Healthy",IF(F5>=60%,"Monitor","Action Required")) -> Healthy
A6: Communication Skills | B6: =COUNTIFS('Raw Data'!$D$2:$D$201,$A6,'Raw Data'!$C$2:$C$201,"Registered") -> 19 | C6: =COUNTIFS('Raw Data'!$D$2:$D$201,$A6,'Raw Data'!$C$2:$C$201,"Waitlisted") -> 2 | D6: =COUNTIFS('Raw Data'!$D$2:$D$201,$A6,'Raw Data'!$C$2:$C$201,"Cancelled") -> 2 | E6: =SUM(B6:D6) -> 23 | F6: =IFERROR(B6/E6,0) -> 0.82608696 | G6: =IFERROR(C6/E6,0) -> 0.086956522 | H6: =IF(F6>=80%,"Healthy",IF(F6>=60%,"Monitor","Action Required")) -> Healthy
A7: Project Management 101 | B7: =COUNTIFS('Raw Data'!$D$2:$D$201,$A7,'Raw Data'!$C$2:$C$201,"Registered") -> 30 | C7: =COUNTIFS('Raw Data'!$D$2:$D$201,$A7,'Raw Data'!$C$2:$C$201,"Waitlisted") -> 3 | D7: =COUNTIFS('Raw Data'!$D$2:$D$201,$A7,'Raw Data'!$C$2:$C$201,"Cancelled") -> 5 | E7: =SUM(B7:D7) -> 38 | F7: =IFERROR(B7/E7,0) -> 0.78947368 | G7: =IFERROR(C7/E7,0) -> 0.078947368 | H7: =IF(F7>=80%,"Healthy",IF(F7>=60%,"Monitor","Action Required")) -> Monitor
A8: SQL for Beginners | B8: =COUNTIFS('Raw Data'!$D$2:$D$201,$A8,'Raw Data'!$C$2:$C$201,"Registered") -> 22 | C8: =COUNTIFS('Raw Data'!$D$2:$D$201,$A8,'Raw Data'!$C$2:$C$201,"Waitlisted") -> 6 | D8: =COUNTIFS('Raw Data'!$D$2:$D$201,$A8,'Raw Data'!$C$2:$C$201,"Cancelled") -> 3 | E8: =SUM(B8:D8) -> 31 | F8: =IFERROR(B8/E8,0) -> 0.70967742 | G8: =IFERROR(C8/E8,0) -> 0.19354839 | H8: =IF(F8>=80%,"Healthy",IF(F8>=60%,"Monitor","Action Required")) -> Monitor
A9: Leadership Essentials | B9: =COUNTIFS('Raw Data'!$D$2:$D$201,$A9,'Raw Data'!$C$2:$C$201,"Registered") -> 31 | C9: =COUNTIFS('Raw Data'!$D$2:$D$201,$A9,'Raw Data'!$C$2:$C$201,"Waitlisted") -> 4 | D9: =COUNTIFS('Raw Data'!$D$2:$D$201,$A9,'Raw Data'!$C$2:$C$201,"Cancelled") -> 1 | E9: =SUM(B9:D9) -> 36 | F9: =IFERROR(B9/E9,0) -> 0.86111111 | G9: =IFERROR(C9/E9,0) -> 0.11111111 | H9: =IF(F9>=80%,"Healthy",IF(F9>=60%,"Monitor","Action Required")) -> Healthy
A10: Total | B10: =SUM(B4:B9) -> 158 | C10: =SUM(C4:C9) -> 26 | D10: =SUM(D4:D9) -> 16 | E10: =SUM(E4:E9) -> 200 | F10: =IFERROR(B10/E10,0) -> 0.79 | G10: =IFERROR(C10/E10,0) -> 0.13 | H10: =IF(F10>=80%,"Healthy",IF(F10>=60%,"Monitor","Action Required")) -> Monitor
A13: Registration Tracker — by Course + Batch
A15: Course | B15: Batch | C15: Registered | D15: Waitlisted | E15: Cancelled
A16: Excel Fundamentals | B16: A | C16: =COUNTIFS('Raw Data'!$D$2:$D$201,$A16,'Raw Data'!$E$2:$E$201,$B16,'Raw Data'!$C$2:$C$201,"Registered") -> 7 | D16: =COUNTIFS('Raw Data'!$D$2:$D$201,$A16,'Raw Data'!$E$2:$E$201,$B16,'Raw Data'!$C$2:$C$201,"Waitlisted") -> 1 | E16: =COUNTIFS('Raw Data'!$D$2:$D$201,$A16,'Raw Data'!$E$2:$E$201,$B16,'Raw Data'!$C$2:$C$201,"Cancelled") -> 0
A17: Excel Fundamentals | B17: B | C17: =COUNTIFS('Raw Data'!$D$2:$D$201,$A17,'Raw Data'!$E$2:$E$201,$B17,'Raw Data'!$C$2:$C$201,"Registered") -> 4 | D17: =COUNTIFS('Raw Data'!$D$2:$D$201,$A17,'Raw Data'!$E$2:$E$201,$B17,'Raw Data'!$C$2:$C$201,"Waitlisted") -> 4 | E17: =COUNTIFS('Raw Data'!$D$2:$D$201,$A17,'Raw Data'!$E$2:$E$201,$B17,'Raw Data'!$C$2:$C$201,"Cancelled") -> 1
A18: Excel Fundamentals | B18: C | C18: =COUNTIFS('Raw Data'!$D$2:$D$201,$A18,'Raw Data'!$E$2:$E$201,$B18,'Raw Data'!$C$2:$C$201,"Registered") -> 7 | D18: =COUNTIFS('Raw Data'!$D$2:$D$201,$A18,'Raw Data'!$E$2:$E$201,$B18,'Raw Data'!$C$2:$C$201,"Waitlisted") -> 2 | E18: =COUNTIFS('Raw Data'!$D$2:$D$201,$A18,'Raw Data'!$E$2:$E$201,$B18,'Raw Data'!$C$2:$C$201,"Cancelled") -> 0
A19: Excel Fundamentals | B19: D | C19: =COUNTIFS('Raw Data'!$D$2:$D$201,$A19,'Raw Data'!$E$2:$E$201,$B19,'Raw Data'!$C$2:$C$201,"Registered") -> 4 | D19: =COUNTIFS('Raw Data'!$D$2:$D$201,$A19,'Raw Data'!$E$2:$E$201,$B19,'Raw Data'!$C$2:$C$201,"Waitlisted") -> 0 | E19: =COUNTIFS('Raw Data'!$D$2:$D$201,$A19,'Raw Data'!$E$2:$E$201,$B19,'Raw Data'!$C$2:$C$201,"Cancelled") -> 2
A20: Data Analytics Basics | B20: A | C20: =COUNTIFS('Raw Data'!$D$2:$D$201,$A20,'Raw Data'!$E$2:$E$201,$B20,'Raw Data'!$C$2:$C$201,"Registered") -> 8 | D20: =COUNTIFS('Raw Data'!$D$2:$D$201,$A20,'Raw Data'!$E$2:$E$201,$B20,'Raw Data'!$C$2:$C$201,"Waitlisted") -> 2 | E20: =COUNTIFS('Raw Data'!$D$2:$D$201,$A20,'Raw Data'!$E$2:$E$201,$B20,'Raw Data'!$C$2:$C$201,"Cancelled") -> 0
A21: Data Analytics Basics | B21: B | C21: =COUNTIFS('Raw Data'!$D$2:$D$201,$A21,'Raw Data'!$E$2:$E$201,$B21,'Raw Data'!$C$2:$C$201,"Registered") -> 6 | D21: =COUNTIFS('Raw Data'!$D$2:$D$201,$A21,'Raw Data'!$E$2:$E$201,$B21,'Raw Data'!$C$2:$C$201,"Waitlisted") -> 0 | E21: =COUNTIFS('Raw Data'!$D$2:$D$201,$A21,'Raw Data'!$E$2:$E$201,$B21,'Raw Data'!$C$2:$C$201,"Cancelled") -> 2
A22: Data Analytics Basics | B22: C | C22: =COUNTIFS('Raw Data'!$D$2:$D$201,$A22,'Raw Data'!$E$2:$E$201,$B22,'Raw Data'!$C$2:$C$201,"Registered") -> 7 | D22: =COUNTIFS('Raw Data'!$D$2:$D$201,$A22,'Raw Data'!$E$2:$E$201,$B22,'Raw Data'!$C$2:$C$201,"Waitlisted") -> 1 | E22: =COUNTIFS('Raw Data'!$D$2:$D$201,$A22,'Raw Data'!$E$2:$E$201,$B22,'Raw Data'!$C$2:$C$201,"Cancelled") -> 0
A23: Data Analytics Basics | B23: D | C23: =COUNTIFS('Raw Data'!$D$2:$D$201,$A23,'Raw Data'!$E$2:$E$201,$B23,'Raw Data'!$C$2:$C$201,"Registered") -> 13 | D23: =COUNTIFS('Raw Data'!$D$2:$D$201,$A23,'Raw Data'!$E$2:$E$201,$B23,'Raw Data'!$C$2:$C$201,"Waitlisted") -> 1 | E23: =COUNTIFS('Raw Data'!$D$2:$D$201,$A23,'Raw Data'!$E$2:$E$201,$B23,'Raw Data'!$C$2:$C$201,"Cancelled") -> 0
A24: Communication Skills | B24: A | C24: =COUNTIFS('Raw Data'!$D$2:$D$201,$A24,'Raw Data'!$E$2:$E$201,$B24,'Raw Data'!$C$2:$C$201,"Registered") -> 7 | D24: =COUNTIFS('Raw Data'!$D$2:$D$201,$A24,'Raw Data'!$E$2:$E$201,$B24,'Raw Data'!$C$2:$C$201,"Waitlisted") -> 0 | E24: =COUNTIFS('Raw Data'!$D$2:$D$201,$A24,'Raw Data'!$E$2:$E$201,$B24,'Raw Data'!$C$2:$C$201,"Cancelled") -> 0
A25: Communication Skills | B25: B | C25: =COUNTIFS('Raw Data'!$D$2:$D$201,$A25,'Raw Data'!$E$2:$E$201,$B25,'Raw Data'!$C$2:$C$201,"Registered") -> 1 | D25: =COUNTIFS('Raw Data'!$D$2:$D$201,$A25,'Raw Data'!$E$2:$E$201,$B25,'Raw Data'!$C$2:$C$201,"Waitlisted") -> 0 | E25: =COUNTIFS('Raw Data'!$D$2:$D$201,$A25,'Raw Data'!$E$2:$E$201,$B25,'Raw Data'!$C$2:$C$201,"Cancelled") -> 1
A26: Communication Skills | B26: C | C26: =COUNTIFS('Raw Data'!$D$2:$D$201,$A26,'Raw Data'!$E$2:$E$201,$B26,'Raw Data'!$C$2:$C$201,"Registered") -> 8 | D26: =COUNTIFS('Raw Data'!$D$2:$D$201,$A26,'Raw Data'!$E$2:$E$201,$B26,'Raw Data'!$C$2:$C$201,"Waitlisted") -> 2 | E26: =COUNTIFS('Raw Data'!$D$2:$D$201,$A26,'Raw Data'!$E$2:$E$201,$B26,'Raw Data'!$C$2:$C$201,"Cancelled") -> 0
A27: Communication Skills | B27: D | C27: =COUNTIFS('Raw Data'!$D$2:$D$201,$A27,'Raw Data'!$E$2:$E$201,$B27,'Raw Data'!$C$2:$C$201,"Registered") -> 3 | D27: =COUNTIFS('Raw Data'!$D$2:$D$201,$A27,'Raw Data'!$E$2:$E$201,$B27,'Raw Data'!$C$2:$C$201,"Waitlisted") -> 0 | E27: =COUNTIFS('Raw Data'!$D$2:$D$201,$A27,'Raw Data'!$E$2:$E$201,$B27,'Raw Data'!$C$2:$C$201,"Cancelled") -> 1
... A39: Leadership Essentials | B39: D | C39: =COUNTIFS('Raw Data'!$D$2:$D$201,$A39,'Raw Data'!$E$2:$E$201,$B39,'Raw Data'!$C$2:$C$201,"Registered") -> 8 | D39: =COUNTIFS('Raw Data'!$D$2:$D$201,$A39,'Raw Data'!$E$2:$E$201,$B39,'Raw Data'!$C$2:$C$201,"Waitlisted") -> 2 | E39: =COUNTIFS('Raw Data'!$D$2:$D$201,$A39,'Raw Data'!$E$2:$E$201,$B39,'Raw Data'!$C$2:$C$201,"Cancelled") -> 1

Sheet Course Schedule
A1: Course Schedule
A3: Course | B3: Batch | C3: Trainer | D3: Session Date | E3: Registered | F3: Capacity | G3: Seats Available | H3: Status
A4: Excel Fundamentals | B4: A | C4: Priya Nair | D4: 46146 | E4: =COUNTIFS('Raw Data'!$D$2:$D$201,$A4,'Raw Data'!$E$2:$E$201,$B4,'Raw Data'!$C$2:$C$201,"Registered") -> 7 | F4: 12 | G4: =F4-E4 -> 5 | H4: =IF(G4<=0,"Full",IF(G4<=2,"Filling Fast","Open")) -> Open
A5: Excel Fundamentals | B5: B | C5: Priya Nair | D5: 46149 | E5: =COUNTIFS('Raw Data'!$D$2:$D$201,$A5,'Raw Data'!$E$2:$E$201,$B5,'Raw Data'!$C$2:$C$201,"Registered") -> 4 | F5: 12 | G5: =F5-E5 -> 8 | H5: =IF(G5<=0,"Full",IF(G5<=2,"Filling Fast","Open")) -> Open
A6: Excel Fundamentals | B6: C | C6: Priya Nair | D6: 46152 | E6: =COUNTIFS('Raw Data'!$D$2:$D$201,$A6,'Raw Data'!$E$2:$E$201,$B6,'Raw Data'!$C$2:$C$201,"Registered") -> 7 | F6: 12 | G6: =F6-E6 -> 5 | H6: =IF(G6<=0,"Full",IF(G6<=2,"Filling Fast","Open")) -> Open
A7: Excel Fundamentals | B7: D | C7: Priya Nair | D7: 46155 | E7: =COUNTIFS('Raw Data'!$D$2:$D$201,$A7,'Raw Data'!$E$2:$E$201,$B7,'Raw Data'!$C$2:$C$201,"Registered") -> 4 | F7: 12 | G7: =F7-E7 -> 8 | H7: =IF(G7<=0,"Full",IF(G7<=2,"Filling Fast","Open")) -> Open
A8: Data Analytics Basics | B8: A | C8: Arjun Mehta | D8: 46158 | E8: =COUNTIFS('Raw Data'!$D$2:$D$201,$A8,'Raw Data'!$E$2:$E$201,$B8,'Raw Data'!$C$2:$C$201,"Registered") -> 8 | F8: 12 | G8: =F8-E8 -> 4 | H8: =IF(G8<=0,"Full",IF(G8<=2,"Filling Fast","Open")) -> Open
A9: Data Analytics Basics | B9: B | C9: Arjun Mehta | D9: 46161 | E9: =COUNTIFS('Raw Data'!$D$2:$D$201,$A9,'Raw Data'!$E$2:$E$201,$B9,'Raw Data'!$C$2:$C$201,"Registered") -> 6 | F9: 12 | G9: =F9-E9 -> 6 | H9: =IF(G9<=0,"Full",IF(G9<=2,"Filling Fast","Open")) -> Open
A10: Data Analytics Basics | B10: C | C10: Arjun Mehta | D10: 46164 | E10: =COUNTIFS('Raw Data'!$D$2:$D$201,$A10,'Raw Data'!$E$2:$E$201,$B10,'Raw Data'!$C$2:$C$201,"Registered") -> 7 | F10: 12 | G10: =F10-E10 -> 5 | H10: =IF(G10<=0,"Full",IF(G10<=2,"Filling Fast","Open")) -> Open
A11: Data Analytics Basics | B11: D | C11: Arjun Mehta | D11: 46167 | E11: =COUNTIFS('Raw Data'!$D$2:$D$201,$A11,'Raw Data'!$E$2:$E$201,$B11,'Raw Data'!$C$2:$C$201,"Registered") -> 13 | F11: 12 | G11: =MAX(0,F4-E4) -> 5 | H11: =IF(E4>F4,"Over Capacity",IF(E4=F4,"Full",IF(G4<=2,"Filling Fast","Open"))) -> Open
A12: Communication Skills | B12: A | C12: Kavya Reddy | D12: 46170 | E12: =COUNTIFS('Raw Data'!$D$2:$D$201,$A12,'Raw Data'!$E$2:$E$201,$B12,'Raw Data'!$C$2:$C$201,"Registered") -> 7 | F12: 12 | G12: =MAX(0,F5-E5) -> 8 | H12: =IF(E5>F5,"Over Capacity",IF(E5=F5,"Full",IF(G5<=2,"Filling Fast","Open"))) -> Open
A13: Communication Skills | B13: B | C13: Kavya Reddy | D13: 46173 | E13: =COUNTIFS('Raw Data'!$D$2:$D$201,$A13,'Raw Data'!$E$2:$E$201,$B13,'Raw Data'!$C$2:$C$201,"Registered") -> 1 | F13: 12 | G13: =MAX(0,F6-E6) -> 5 | H13: =IF(E6>F6,"Over Capacity",IF(E6=F6,"Full",IF(G6<=2,"Filling Fast","Open"))) -> Open
A14: Communication Skills | B14: C | C14: Kavya Reddy | D14: 46176 | E14: =COUNTIFS('Raw Data'!$D$2:$D$201,$A14,'Raw Data'!$E$2:$E$201,$B14,'Raw Data'!$C$2:$C$201,"Registered") -> 8 | F14: 12 | G14: =MAX(0,F7-E7) -> 8 | H14: =IF(E7>F7,"Over Capacity",IF(E7=F7,"Full",IF(G7<=2,"Filling Fast","Open"))) -> Open
A15: Communication Skills | B15: D | C15: Kavya Reddy | D15: 46179 | E15: =COUNTIFS('Raw Data'!$D$2:$D$201,$A15,'Raw Data'!$E$2:$E$201,$B15,'Raw Data'!$C$2:$C$201,"Registered") -> 3 | F15: 12 | G15: =MAX(0,F8-E8) -> 4 | H15: =IF(E8>F8,"Over Capacity",IF(E8=F8,"Full",IF(G8<=2,"Filling Fast","Open"))) -> Open
A16: Project Management 101 | B16: A | C16: Rohan Iyer | D16: 46182 | E16: =COUNTIFS('Raw Data'!$D$2:$D$201,$A16,'Raw Data'!$E$2:$E$201,$B16,'Raw Data'!$C$2:$C$201,"Registered") -> 7 | F16: 12 | G16: =MAX(0,F9-E9) -> 6 | H16: =IF(E9>F9,"Over Capacity",IF(E9=F9,"Full",IF(G9<=2,"Filling Fast","Open"))) -> Open
A17: Project Management 101 | B17: B | C17: Rohan Iyer | D17: 46185 | E17: =COUNTIFS('Raw Data'!$D$2:$D$201,$A17,'Raw Data'!$E$2:$E$201,$B17,'Raw Data'!$C$2:$C$201,"Registered") -> 10 | F17: 12 | G17: =MAX(0,F10-E10) -> 5 | H17: =IF(E10>F10,"Over Capacity",IF(E10=F10,"Full",IF(G10<=2,"Filling Fast","Open"))) -> Open
A18: Project Management 101 | B18: C | C18: Rohan Iyer | D18: 46188 | E18: =COUNTIFS('Raw Data'!$D$2:$D$201,$A18,'Raw Data'!$E$2:$E$201,$B18,'Raw Data'!$C$2:$C$201,"Registered") -> 10 | F18: 12 | G18: =MAX(0,F11-E11) -> 0 | H18: =IF(E11>F11,"Over Capacity",IF(E11=F11,"Full",IF(G11<=2,"Filling Fast","Open"))) -> Over Capacity
A19: Project Management 101 | B19: D | C19: Rohan Iyer | D19: 46191 | E19: =COUNTIFS('Raw Data'!$D$2:$D$201,$A19,'Raw Data'!$E$2:$E$201,$B19,'Raw Data'!$C$2:$C$201,"Registered") -> 3 | F19: 12 | G19: =MAX(0,F12-E12) -> 5 | H19: =IF(E12>F12,"Over Capacity",IF(E12=F12,"Full",IF(G12<=2,"Filling Fast","Open"))) -> Open
A20: SQL for Beginners | B20: A | C20: Sneha Kulkarni | D20: 46194 | E20: =COUNTIFS('Raw Data'!$D$2:$D$201,$A20,'Raw Data'!$E$2:$E$201,$B20,'Raw Data'!$C$2:$C$201,"Registered") -> 5 | F20: 12 | G20: =MAX(0,F13-E13) -> 11 | H20: =IF(E13>F13,"Over Capacity",IF(E13=F13,"Full",IF(G13<=2,"Filling Fast","Open"))) -> Open
A21: SQL for Beginners | B21: B | C21: Sneha Kulkarni | D21: 46197 | E21: =COUNTIFS('Raw Data'!$D$2:$D$201,$A21,'Raw Data'!$E$2:$E$201,$B21,'Raw Data'!$C$2:$C$201,"Registered") -> 9 | F21: 12 | G21: =MAX(0,F14-E14) -> 4 | H21: =IF(E14>F14,"Over Capacity",IF(E14=F14,"Full",IF(G14<=2,"Filling Fast","Open"))) -> Open
A22: SQL for Beginners | B22: C | C22: Sneha Kulkarni | D22: 46200 | E22: =COUNTIFS('Raw Data'!$D$2:$D$201,$A22,'Raw Data'!$E$2:$E$201,$B22,'Raw Data'!$C$2:$C$201,"Registered") -> 3 | F22: 12 | G22: =MAX(0,F15-E15) -> 9 | H22: =IF(E15>F15,"Over Capacity",IF(E15=F15,"Full",IF(G15<=2,"Filling Fast","Open"))) -> Open
... A27: Leadership Essentials | B27: D | C27: Vikram Rao | D27: 46215 | E27: =COUNTIFS('Raw Data'!$D$2:$D$201,$A27,'Raw Data'!$E$2:$E$201,$B27,'Raw Data'!$C$2:$C$201,"Registered") -> 8 | F27: 12 | G27: =MAX(0,F20-E20) -> 7 | H27: =IF(E20>F20,"Over Capacity",IF(E20=F20,"Full",IF(G20<=2,"Filling Fast","Open"))) -> Open
A29: Assumption: Capacity fixed at 12 seats per course-batch session (blue = input cell).

Sheet Attendance Tracker
A1: Attendance Tracker
A3: Course | B3: Present | C3: Absent | D3: Registered Total | E3: Attendance Rate | F3: Absence Rate | G3: Attendance Health
A4: Excel Fundamentals | B4: =COUNTIFS('Raw Data'!$D$2:$D$201,$A4,'Raw Data'!$H$2:$H$201,"Present") -> 20 | C4: =COUNTIFS('Raw Data'!$D$2:$D$201,$A4,'Raw Data'!$H$2:$H$201,"Absent") -> 2 | D4: =COUNTIFS('Raw Data'!$D$2:$D$201,$A4,'Raw Data'!$C$2:$C$201,"Registered") -> 22 | E4: =IFERROR(B4/D4,0) -> 0.90909091 | F4: =IFERROR(C4/D4,0) -> 0.090909091 | G4: =IF(D4=0,"No Data",IF(E4>=0.9,"Healthy",IF(E4>=0.8,"Monitor","Action Required"))) -> Healthy
A5: Data Analytics Basics | B5: =COUNTIFS('Raw Data'!$D$2:$D$201,$A5,'Raw Data'!$H$2:$H$201,"Present") -> 32 | C5: =COUNTIFS('Raw Data'!$D$2:$D$201,$A5,'Raw Data'!$H$2:$H$201,"Absent") -> 2 | D5: =COUNTIFS('Raw Data'!$D$2:$D$201,$A5,'Raw Data'!$C$2:$C$201,"Registered") -> 34 | E5: =IFERROR(B5/D5,0) -> 0.94117647 | F5: =IFERROR(C5/D5,0) -> 0.058823529 | G5: =IF(D5=0,"No Data",IF(E5>=0.9,"Healthy",IF(E5>=0.8,"Monitor","Action Required"))) -> Healthy
A6: Communication Skills | B6: =COUNTIFS('Raw Data'!$D$2:$D$201,$A6,'Raw Data'!$H$2:$H$201,"Present") -> 15 | C6: =COUNTIFS('Raw Data'!$D$2:$D$201,$A6,'Raw Data'!$H$2:$H$201,"Absent") -> 4 | D6: =COUNTIFS('Raw Data'!$D$2:$D$201,$A6,'Raw Data'!$C$2:$C$201,"Registered") -> 19 | E6: =IFERROR(B6/D6,0) -> 0.78947368 | F6: =IFERROR(C6/D6,0) -> 0.21052632 | G6: =IF(D6=0,"No Data",IF(E6>=0.9,"Healthy",IF(E6>=0.8,"Monitor","Action Required"))) -> Action Required
A7: Project Management 101 | B7: =COUNTIFS('Raw Data'!$D$2:$D$201,$A7,'Raw Data'!$H$2:$H$201,"Present") -> 24 | C7: =COUNTIFS('Raw Data'!$D$2:$D$201,$A7,'Raw Data'!$H$2:$H$201,"Absent") -> 6 | D7: =COUNTIFS('Raw Data'!$D$2:$D$201,$A7,'Raw Data'!$C$2:$C$201,"Registered") -> 30 | E7: =IFERROR(B7/D7,0) -> 0.8 | F7: =IFERROR(C7/D7,0) -> 0.2 | G7: =IF(D7=0,"No Data",IF(E7>=0.9,"Healthy",IF(E7>=0.8,"Monitor","Action Required"))) -> Monitor
A8: SQL for Beginners | B8: =COUNTIFS('Raw Data'!$D$2:$D$201,$A8,'Raw Data'!$H$2:$H$201,"Present") -> 18 | C8: =COUNTIFS('Raw Data'!$D$2:$D$201,$A8,'Raw Data'!$H$2:$H$201,"Absent") -> 4 | D8: =COUNTIFS('Raw Data'!$D$2:$D$201,$A8,'Raw Data'!$C$2:$C$201,"Registered") -> 22 | E8: =IFERROR(B8/D8,0) -> 0.81818182 | F8: =IFERROR(C8/D8,0) -> 0.18181818 | G8: =IF(D8=0,"No Data",IF(E8>=0.9,"Healthy",IF(E8>=0.8,"Monitor","Action Required"))) -> Monitor
A9: Leadership Essentials | B9: =COUNTIFS('Raw Data'!$D$2:$D$201,$A9,'Raw Data'!$H$2:$H$201,"Present") -> 24 | C9: =COUNTIFS('Raw Data'!$D$2:$D$201,$A9,'Raw Data'!$H$2:$H$201,"Absent") -> 7 | D9: =COUNTIFS('Raw Data'!$D$2:$D$201,$A9,'Raw Data'!$C$2:$C$201,"Registered") -> 31 | E9: =IFERROR(B9/D9,0) -> 0.77419355 | F9: =IFERROR(C9/D9,0) -> 0.22580645 | G9: =IF(D9=0,"No Data",IF(E9>=0.9,"Healthy",IF(E9>=0.8,"Monitor","Action Required"))) -> Action Required
A10: Total | B10: =SUM(B4:B9) -> 133 | C10: =SUM(C4:C9) -> 25 | D10: =SUM(D4:D9) -> 158 | E10: =IFERROR(B10/D10,0) -> 0.84177215 | F10: =IFERROR(C10/D10,0) -> 0.15822785 | G10: =IF(E10>=0.9,"Healthy",IF(E10>=0.8,"Monitor","Action Required")) -> Monitor

Sheet Completion Dashboard
A1: Completion Dashboard
A3: Course | B3: Completed | C3: In Progress | D3: Dropped | E3: Registered Total | F3: Completion Rate | G3: Avg Feedback Score | H3: Completion Health | I3: Feedback Health
A4: Excel Fundamentals | B4: =COUNTIFS('Raw Data'!$D$2:$D$201,$A4,'Raw Data'!$I$2:$I$201,"Completed") -> 18 | C4: =COUNTIFS('Raw Data'!$D$2:$D$201,$A4,'Raw Data'!$I$2:$I$201,"In Progress") -> 1 | D4: =COUNTIFS('Raw Data'!$D$2:$D$201,$A4,'Raw Data'!$I$2:$I$201,"Dropped") -> 1 | E4: =COUNTIFS('Raw Data'!$D$2:$D$201,$A4,'Raw Data'!$C$2:$C$201,"Registered") -> 22 | F4: =IFERROR(B4/E4,0) -> 0.81818182 | G4: =IFERROR(AVERAGEIFS('Raw Data'!$J$2:$J$201,'Raw Data'!$D$2:$D$201,$A4,'Raw Data'!$I$2:$I$201,"Completed"),0) -> 4.0555556 | H4: =IF(E4=0,"No Data",IF(F4>=0.8,"Healthy",IF(F4>=0.6,"Monitor","Action Required"))) -> Healthy | I4: =IF(B4=0,"No Data",IF(G4>=4,"Positive",IF(G4>=3,"Monitor","Action Required"))) -> Positive
A5: Data Analytics Basics | B5: =COUNTIFS('Raw Data'!$D$2:$D$201,$A5,'Raw Data'!$I$2:$I$201,"Completed") -> 22 | C5: =COUNTIFS('Raw Data'!$D$2:$D$201,$A5,'Raw Data'!$I$2:$I$201,"In Progress") -> 4 | D5: =COUNTIFS('Raw Data'!$D$2:$D$201,$A5,'Raw Data'!$I$2:$I$201,"Dropped") -> 6 | E5: =COUNTIFS('Raw Data'!$D$2:$D$201,$A5,'Raw Data'!$C$2:$C$201,"Registered") -> 34 | F5: =IFERROR(B5/E5,0) -> 0.64705882 | G5: =IFERROR(AVERAGEIFS('Raw Data'!$J$2:$J$201,'Raw Data'!$D$2:$D$201,$A5,'Raw Data'!$I$2:$I$201,"Completed"),0) -> 3.9545455 | H5: =IF(E5=0,"No Data",IF(F5>=0.8,"Healthy",IF(F5>=0.6,"Monitor","Action Required"))) -> Monitor | I5: =IF(B5=0,"No Data",IF(G5>=4,"Positive",IF(G5>=3,"Monitor","Action Required"))) -> Monitor
A6: Communication Skills | B6: =COUNTIFS('Raw Data'!$D$2:$D$201,$A6,'Raw Data'!$I$2:$I$201,"Completed") -> 10 | C6: =COUNTIFS('Raw Data'!$D$2:$D$201,$A6,'Raw Data'!$I$2:$I$201,"In Progress") -> 4 | D6: =COUNTIFS('Raw Data'!$D$2:$D$201,$A6,'Raw Data'!$I$2:$I$201,"Dropped") -> 1 | E6: =COUNTIFS('Raw Data'!$D$2:$D$201,$A6,'Raw Data'!$C$2:$C$201,"Registered") -> 19 | F6: =IFERROR(B6/E6,0) -> 0.52631579 | G6: =IFERROR(AVERAGEIFS('Raw Data'!$J$2:$J$201,'Raw Data'!$D$2:$D$201,$A6,'Raw Data'!$I$2:$I$201,"Completed"),0) -> 4.2 | H6: =IF(E6=0,"No Data",IF(F6>=0.8,"Healthy",IF(F6>=0.6,"Monitor","Action Required"))) -> Action Required | I6: =IF(B6=0,"No Data",IF(G6>=4,"Positive",IF(G6>=3,"Monitor","Action Required"))) -> Positive
A7: Project Management 101 | B7: =COUNTIFS('Raw Data'!$D$2:$D$201,$A7,'Raw Data'!$I$2:$I$201,"Completed") -> 17 | C7: =COUNTIFS('Raw Data'!$D$2:$D$201,$A7,'Raw Data'!$I$2:$I$201,"In Progress") -> 4 | D7: =COUNTIFS('Raw Data'!$D$2:$D$201,$A7,'Raw Data'!$I$2:$I$201,"Dropped") -> 3 | E7: =COUNTIFS('Raw Data'!$D$2:$D$201,$A7,'Raw Data'!$C$2:$C$201,"Registered") -> 30 | F7: =IFERROR(B7/E7,0) -> 0.56666667 | G7: =IFERROR(AVERAGEIFS('Raw Data'!$J$2:$J$201,'Raw Data'!$D$2:$D$201,$A7,'Raw Data'!$I$2:$I$201,"Completed"),0) -> 4.2352941 | H7: =IF(E7=0,"No Data",IF(F7>=0.8,"Healthy",IF(F7>=0.6,"Monitor","Action Required"))) -> Action Required | I7: =IF(B7=0,"No Data",IF(G7>=4,"Positive",IF(G7>=3,"Monitor","Action Required"))) -> Positive
A8: SQL for Beginners | B8: =COUNTIFS('Raw Data'!$D$2:$D$201,$A8,'Raw Data'!$I$2:$I$201,"Completed") -> 12 | C8: =COUNTIFS('Raw Data'!$D$2:$D$201,$A8,'Raw Data'!$I$2:$I$201,"In Progress") -> 2 | D8: =COUNTIFS('Raw Data'!$D$2:$D$201,$A8,'Raw Data'!$I$2:$I$201,"Dropped") -> 4 | E8: =COUNTIFS('Raw Data'!$D$2:$D$201,$A8,'Raw Data'!$C$2:$C$201,"Registered") -> 22 | F8: =IFERROR(B8/E8,0) -> 0.54545455 | G8: =IFERROR(AVERAGEIFS('Raw Data'!$J$2:$J$201,'Raw Data'!$D$2:$D$201,$A8,'Raw Data'!$I$2:$I$201,"Completed"),0) -> 4.5833333 | H8: =IF(E8=0,"No Data",IF(F8>=0.8,"Healthy",IF(F8>=0.6,"Monitor","Action Required"))) -> Action Required | I8: =IF(B8=0,"No Data",IF(G8>=4,"Positive",IF(G8>=3,"Monitor","Action Required"))) -> Positive
A9: Leadership Essentials | B9: =COUNTIFS('Raw Data'!$D$2:$D$201,$A9,'Raw Data'!$I$2:$I$201,"Completed") -> 19 | C9: =COUNTIFS('Raw Data'!$D$2:$D$201,$A9,'Raw Data'!$I$2:$I$201,"In Progress") -> 4 | D9: =COUNTIFS('Raw Data'!$D$2:$D$201,$A9,'Raw Data'!$I$2:$I$201,"Dropped") -> 1 | E9: =COUNTIFS('Raw Data'!$D$2:$D$201,$A9,'Raw Data'!$C$2:$C$201,"Registered") -> 31 | F9: =IFERROR(B9/E9,0) -> 0.61290323 | G9: =IFERROR(AVERAGEIFS('Raw Data'!$J$2:$J$201,'Raw Data'!$D$2:$D$201,$A9,'Raw Data'!$I$2:$I$201,"Completed"),0) -> 4.1052632 | H9: =IF(E9=0,"No Data",IF(F9>=0.8,"Healthy",IF(F9>=0.6,"Monitor","Action Required"))) -> Monitor | I9: =IF(B9=0,"No Data",IF(G9>=4,"Positive",IF(G9>=3,"Monitor","Action Required"))) -> Positive
A10: Total | B10: =SUM(B4:B9) -> 98 | C10: =SUM(C4:C9) -> 19 | D10: =SUM(D4:D9) -> 16 | E10: =SUM(E4:E9) -> 158 | F10: =IFERROR(B10/E10,0) -> 0.62025316 | G10: =IFERROR(AVERAGEIFS('Raw Data'!$J$2:$J$201,'Raw Data'!$I$2:$I$201,"Completed"),0) -> 4.1530612 | H10: =IF(F10>=0.8,"Healthy",IF(F10>=0.6,"Monitor","Action Required")) -> Monitor | I10: =IF(G10>=4,"Positive",IF(G10>=3,"Monitor","Action Required")) -> Positive

Sheet Exception & Action Tracker
A1: Exception & Action Tracker
A2: Auto-extracted from Raw Data: every participant with an open pending action (INDEX/MATCH against the hidden Exception Rank helper column).
A4: Action ID | B4: Participant ID | C4: Participant Name | D4: Course | E4: Batch | F4: Registration Status | G4: Pending Action | H4: Priority | I4: Owner | J4: Due Date | K4: Status
A5: ="ACT-"&TEXT(ROW()-4,"000") -> ACT-001 | B5: =IFERROR(INDEX('Raw Data'!$A$2:$A$201,MATCH(ROW()-4,'Raw Data'!$L$2:$L$201,0)),"") -> P003 | C5: =IFERROR(INDEX('Raw Data'!$B$2:$B$201,MATCH(ROW()-4,'Raw Data'!$L$2:$L$201,0)),"") -> Ishaan Rana | D5: =IFERROR(INDEX('Raw Data'!$D$2:$D$201,MATCH(ROW()-4,'Raw Data'!$L$2:$L$201,0)),"") -> Communication Skills | E5: =IFERROR(INDEX('Raw Data'!$E$2:$E$201,MATCH(ROW()-4,'Raw Data'!$L$2:$L$201,0)),"") -> A | F5: =IFERROR(INDEX('Raw Data'!$C$2:$C$201,MATCH(ROW()-4,'Raw Data'!$L$2:$L$201,0)),"") -> Registered | G5: =IFERROR(INDEX('Raw Data'!$K$2:$K$201,MATCH(ROW()-4,'Raw Data'!$L$2:$L$201,0)),"") -> Collect interim feedback | H5: =IF($G5="","",IF(OR($G5="Follow up on absence",$G5="Resolve waitlist",$G5="Follow up - dropped participant"),"High","Medium")) -> Medium | I5: =IF($G5="","",IF($G5="Resolve waitlist","Program Coordinator","Learning Ops")) -> Learning Ops | J5: =IFERROR(INDEX('Raw Data'!$G$2:$G$201,MATCH(ROW()-4,'Raw Data'!$L$2:$L$201,0))+7,"") -> 46177 | K5: =IF($G5="","","Open") -> Open
A6: ="ACT-"&TEXT(ROW()-4,"000") -> ACT-002 | B6: =IFERROR(INDEX('Raw Data'!$A$2:$A$201,MATCH(ROW()-4,'Raw Data'!$L$2:$L$201,0)),"") -> P005 | C6: =IFERROR(INDEX('Raw Data'!$B$2:$B$201,MATCH(ROW()-4,'Raw Data'!$L$2:$L$201,0)),"") -> Deepak Joshi | D6: =IFERROR(INDEX('Raw Data'!$D$2:$D$201,MATCH(ROW()-4,'Raw Data'!$L$2:$L$201,0)),"") -> Data Analytics Basics | E6: =IFERROR(INDEX('Raw Data'!$E$2:$E$201,MATCH(ROW()-4,'Raw Data'!$L$2:$L$201,0)),"") -> D | F6: =IFERROR(INDEX('Raw Data'!$C$2:$C$201,MATCH(ROW()-4,'Raw Data'!$L$2:$L$201,0)),"") -> Registered | G6: =IFERROR(INDEX('Raw Data'!$K$2:$K$201,MATCH(ROW()-4,'Raw Data'!$L$2:$L$201,0)),"") -> Collect interim feedback | H6: =IF($G6="","",IF(OR($G6="Follow up on absence",$G6="Resolve waitlist",$G6="Follow up - dropped participant"),"High","Medium")) -> Medium | I6: =IF($G6="","",IF($G6="Resolve waitlist","Program Coordinator","Learning Ops")) -> Learning Ops | J6: =IFERROR(INDEX('Raw Data'!$G$2:$G$201,MATCH(ROW()-4,'Raw Data'!$L$2:$L$201,0))+7,"") -> 46174 | K6: =IF($G6="","","Open") -> Open
A7: ="ACT-"&TEXT(ROW()-4,"000") -> ACT-003 | B7: =IFERROR(INDEX('Raw Data'!$A$2:$A$201,MATCH(ROW()-4,'Raw Data'!$L$2:$L$201,0)),"") -> P006 | C7: =IFERROR(INDEX('Raw Data'!$B$2:$B$201,MATCH(ROW()-4,'Raw Data'!$L$2:$L$201,0)),"") -> Sandeep Chawla | D7: =IFERROR(INDEX('Raw Data'!$D$2:$D$201,MATCH(ROW()-4,'Raw Data'!$L$2:$L$201,0)),"") -> Data Analytics Basics | E7: =IFERROR(INDEX('Raw Data'!$E$2:$E$201,MATCH(ROW()-4,'Raw Data'!$L$2:$L$201,0)),"") -> B | F7: =IFERROR(INDEX('Raw Data'!$C$2:$C$201,MATCH(ROW()-4,'Raw Data'!$L$2:$L$201,0)),"") -> Registered | G7: =IFERROR(INDEX('Raw Data'!$K$2:$K$201,MATCH(ROW()-4,'Raw Data'!$L$2:$L$201,0)),"") -> Follow up - dropped participant | H7: =IF($G7="","",IF(OR($G7="Follow up on absence",$G7="Resolve waitlist",$G7="Follow up - dropped participant"),"High","Medium")) -> High | I7: =IF($G7="","",IF($G7="Resolve waitlist","Program Coordinator","Learning Ops")) -> Learning Ops | J7: =IFERROR(INDEX('Raw Data'!$G$2:$G$201,MATCH(ROW()-4,'Raw Data'!$L$2:$L$201,0))+7,"") -> 46168 | K7: =IF($G7="","","Open") -> Open
A8: ="ACT-"&TEXT(ROW()-4,"000") -> ACT-004 | B8: =IFERROR(INDEX('Raw Data'!$A$2:$A$201,MATCH(ROW()-4,'Raw Data'!$L$2:$L$201,0)),"") -> P007 | C8: =IFERROR(INDEX('Raw Data'!$B$2:$B$201,MATCH(ROW()-4,'Raw Data'!$L$2:$L$201,0)),"") -> Anil Joshi | D8: =IFERROR(INDEX('Raw Data'!$D$2:$D$201,MATCH(ROW()-4,'Raw Data'!$L$2:$L$201,0)),"") -> SQL for Beginners | E8: =IFERROR(INDEX('Raw Data'!$E$2:$E$201,MATCH(ROW()-4,'Raw Data'!$L$2:$L$201,0)),"") -> B | F8: =IFERROR(INDEX('Raw Data'!$C$2:$C$201,MATCH(ROW()-4,'Raw Data'!$L$2:$L$201,0)),"") -> Registered | G8: =IFERROR(INDEX('Raw Data'!$K$2:$K$201,MATCH(ROW()-4,'Raw Data'!$L$2:$L$201,0)),"") -> Send completion certificate | H8: =IF($G8="","",IF(OR($G8="Follow up on absence",$G8="Resolve waitlist",$G8="Follow up - dropped participant"),"High","Medium")) -> Medium | I8: =IF($G8="","",IF($G8="Resolve waitlist","Program Coordinator","Learning Ops")) -> Learning Ops | J8: =IFERROR(INDEX('Raw Data'!$G$2:$G$201,MATCH(ROW()-4,'Raw Data'!$L$2:$L$201,0))+7,"") -> 46204 | K8: =IF($G8="","","Open") -> Open
A9: ="ACT-"&TEXT(ROW()-4,"000") -> ACT-005 | B9: =IFERROR(INDEX('Raw Data'!$A$2:$A$201,MATCH(ROW()-4,'Raw Data'!$L$2:$L$201,0)),"") -> P011 | C9: =IFERROR(INDEX('Raw Data'!$B$2:$B$201,MATCH(ROW()-4,'Raw Data'!$L$2:$L$201,0)),"") -> Reyansh Nayar | D9: =IFERROR(INDEX('Raw Data'!$D$2:$D$201,MATCH(ROW()-4,'Raw Data'!$L$2:$L$201,0)),"") -> Leadership Essentials | E9: =IFERROR(INDEX('Raw Data'!$E$2:$E$201,MATCH(ROW()-4,'Raw Data'!$L$2:$L$201,0)),"") -> B | F9: =IFERROR(INDEX('Raw Data'!$C$2:$C$201,MATCH(ROW()-4,'Raw Data'!$L$2:$L$201,0)),"") -> Registered | G9: =IFERROR(INDEX('Raw Data'!$K$2:$K$201,MATCH(ROW()-4,'Raw Data'!$L$2:$L$201,0)),"") -> Follow up on absence | H9: =IF($G9="","",IF(OR($G9="Follow up on absence",$G9="Resolve waitlist",$G9="Follow up - dropped participant"),"High","Medium")) -> High | I9: =IF($G9="","",IF($G9="Resolve waitlist","Program Coordinator","Learning Ops")) -> Learning Ops | J9: =IFERROR(INDEX('Raw Data'!$G$2:$G$201,MATCH(ROW()-4,'Raw Data'!$L$2:$L$201,0))+7,"") -> 46216 | K9: =IF($G9="","","Open") -> Open
A10: ="ACT-"&TEXT(ROW()-4,"000") -> ACT-006 | B10: =IFERROR(INDEX('Raw Data'!$A$2:$A$201,MATCH(ROW()-4,'Raw Data'!$L$2:$L$201,0)),"") -> P012 | C10: =IFERROR(INDEX('Raw Data'!$B$2:$B$201,MATCH(ROW()-4,'Raw Data'!$L$2:$L$201,0)),"") -> Anika Iyer | D10: =IFERROR(INDEX('Raw Data'!$D$2:$D$201,MATCH(ROW()-4,'Raw Data'!$L$2:$L$201,0)),"") -> Data Analytics Basics | E10: =IFERROR(INDEX('Raw Data'!$E$2:$E$201,MATCH(ROW()-4,'Raw Data'!$L$2:$L$201,0)),"") -> A | F10: =IFERROR(INDEX('Raw Data'!$C$2:$C$201,MATCH(ROW()-4,'Raw Data'!$L$2:$L$201,0)),"") -> Waitlisted | G10: =IFERROR(INDEX('Raw Data'!$K$2:$K$201,MATCH(ROW()-4,'Raw Data'!$L$2:$L$201,0)),"") -> Resolve waitlist | H10: =IF($G10="","",IF(OR($G10="Follow up on absence",$G10="Resolve waitlist",$G10="Follow up - dropped participant"),"High","Medium")) -> High | I10: =IF($G10="","",IF($G10="Resolve waitlist","Program Coordinator","Learning Ops")) -> Program Coordinator | J10: =IFERROR(INDEX('Raw Data'!$G$2:$G$201,MATCH(ROW()-4,'Raw Data'!$L$2:$L$201,0))+7,"") -> 46165 | K10: =IF($G10="","","Open") -> Open
A11: ="ACT-"&TEXT(ROW()-4,"000") -> ACT-007 | B11: =IFERROR(INDEX('Raw Data'!$A$2:$A$201,MATCH(ROW()-4,'Raw Data'!$L$2:$L$201,0)),"") -> P013 | C11: =IFERROR(INDEX('Raw Data'!$B$2:$B$201,MATCH(ROW()-4,'Raw Data'!$L$2:$L$201,0)),"") -> Gaurav Bhat | D11: =IFERROR(INDEX('Raw Data'!$D$2:$D$201,MATCH(ROW()-4,'Raw Data'!$L$2:$L$201,0)),"") -> Excel Fundamentals | E11: =IFERROR(INDEX('Raw Data'!$E$2:$E$201,MATCH(ROW()-4,'Raw Data'!$L$2:$L$201,0)),"") -> D | F11: =IFERROR(INDEX('Raw Data'!$C$2:$C$201,MATCH(ROW()-4,'Raw Data'!$L$2:$L$201,0)),"") -> Registered | G11: =IFERROR(INDEX('Raw Data'!$K$2:$K$201,MATCH(ROW()-4,'Raw Data'!$L$2:$L$201,0)),"") -> Follow up - dropped participant | H11: =IF($G11="","",IF(OR($G11="Follow up on absence",$G11="Resolve waitlist",$G11="Follow up - dropped participant"),"High","Medium")) -> High | I11: =IF($G11="","",IF($G11="Resolve waitlist","Program Coordinator","Learning Ops")) -> Learning Ops | J11: =IFERROR(INDEX('Raw Data'!$G$2:$G$201,MATCH(ROW()-4,'Raw Data'!$L$2:$L$201,0))+7,"") -> 46162 | K11: =IF($G11="","","Open") -> Open
A12: ="ACT-"&TEXT(ROW()-4,"000") -> ACT-008 | B12: =IFERROR(INDEX('Raw Data'!$A$2:$A$201,MATCH(ROW()-4,'Raw Data'!$L$2:$L$201,0)),"") -> P015 | C12: =IFERROR(INDEX('Raw Data'!$B$2:$B$201,MATCH(ROW()-4,'Raw Data'!$L$2:$L$201,0)),"") -> Aadhya Das | D12: =IFERROR(INDEX('Raw Data'!$D$2:$D$201,MATCH(ROW()-4,'Raw Data'!$L$2:$L$201,0)),"") -> SQL for Beginners | E12: =IFERROR(INDEX('Raw Data'!$E$2:$E$201,MATCH(ROW()-4,'Raw Data'!$L$2:$L$201,0)),"") -> D | F12: =IFERROR(INDEX('Raw Data'!$C$2:$C$201,MATCH(ROW()-4,'Raw Data'!$L$2:$L$201,0)),"") -> Waitlisted | G12: =IFERROR(INDEX('Raw Data'!$K$2:$K$201,MATCH(ROW()-4,'Raw Data'!$L$2:$L$201,0)),"") -> Resolve waitlist | H12: =IF($G12="","",IF(OR($G12="Follow up on absence",$G12="Resolve waitlist",$G12="Follow up - dropped participant"),"High","Medium")) -> High | I12: =IF($G12="","",IF($G12="Resolve waitlist","Program Coordinator","Learning Ops")) -> Program Coordinator | J12: =IFERROR(INDEX('Raw Data'!$G$2:$G$201,MATCH(ROW()-4,'Raw Data'!$L$2:$L$201,0))+7,"") -> 46210 | K12: =IF($G12="","","Open") -> Open
A13: ="ACT-"&TEXT(ROW()-4,"000") -> ACT-009 | B13: =IFERROR(INDEX('Raw Data'!$A$2:$A$201,MATCH(ROW()-4,'Raw Data'!$L$2:$L$201,0)),"") -> P016 | C13: =IFERROR(INDEX('Raw Data'!$B$2:$B$201,MATCH(ROW()-4,'Raw Data'!$L$2:$L$201,0)),"") -> Aadhya Mukherjee | D13: =IFERROR(INDEX('Raw Data'!$D$2:$D$201,MATCH(ROW()-4,'Raw Data'!$L$2:$L$201,0)),"") -> Communication Skills | E13: =IFERROR(INDEX('Raw Data'!$E$2:$E$201,MATCH(ROW()-4,'Raw Data'!$L$2:$L$201,0)),"") -> C | F13: =IFERROR(INDEX('Raw Data'!$C$2:$C$201,MATCH(ROW()-4,'Raw Data'!$L$2:$L$201,0)),"") -> Waitlisted | G13: =IFERROR(INDEX('Raw Data'!$K$2:$K$201,MATCH(ROW()-4,'Raw Data'!$L$2:$L$201,0)),"") -> Resolve waitlist | H13: =IF($G13="","",IF(OR($G13="Follow up on absence",$G13="Resolve waitlist",$G13="Follow up - dropped participant"),"High","Medium")) -> High | I13: =IF($G13="","",IF($G13="Resolve waitlist","Program Coordinator","Learning Ops")) -> Program Coordinator | J13: =IFERROR(INDEX('Raw Data'!$G$2:$G$201,MATCH(ROW()-4,'Raw Data'!$L$2:$L$201,0))+7,"") -> 46183 | K13: =IF($G13="","","Open") -> Open
A14: ="ACT-"&TEXT(ROW()-4,"000") -> ACT-010 | B14: =IFERROR(INDEX('Raw Data'!$A$2:$A$201,MATCH(ROW()-4,'Raw Data'!$L$2:$L$201,0)),"") -> P018 | C14: =IFERROR(INDEX('Raw Data'!$B$2:$B$201,MATCH(ROW()-4,'Raw Data'!$L$2:$L$201,0)),"") -> Neha Mehta | D14: =IFERROR(INDEX('Raw Data'!$D$2:$D$201,MATCH(ROW()-4,'Raw Data'!$L$2:$L$201,0)),"") -> SQL for Beginners | E14: =IFERROR(INDEX('Raw Data'!$E$2:$E$201,MATCH(ROW()-4,'Raw Data'!$L$2:$L$201,0)),"") -> A | F14: =IFERROR(INDEX('Raw Data'!$C$2:$C$201,MATCH(ROW()-4,'Raw Data'!$L$2:$L$201,0)),"") -> Registered | G14: =IFERROR(INDEX('Raw Data'!$K$2:$K$201,MATCH(ROW()-4,'Raw Data'!$L$2:$L$201,0)),"") -> Follow up - dropped participant | H14: =IF($G14="","",IF(OR($G14="Follow up on absence",$G14="Resolve waitlist",$G14="Follow up - dropped participant"),"High","Medium")) -> High | I14: =IF($G14="","",IF($G14="Resolve waitlist","Program Coordinator","Learning Ops")) -> Learning Ops | J14: =IFERROR(INDEX('Raw Data'!$G$2:$G$201,MATCH(ROW()-4,'Raw Data'!$L$2:$L$201,0))+7,"") -> 46201 | K14: =IF($G14="","","Open") -> Open
A15: ="ACT-"&TEXT(ROW()-4,"000") -> ACT-011 | B15: =IFERROR(INDEX('Raw Data'!$A$2:$A$201,MATCH(ROW()-4,'Raw Data'!$L$2:$L$201,0)),"") -> P021 | C15: =IFERROR(INDEX('Raw Data'!$B$2:$B$201,MATCH(ROW()-4,'Raw Data'!$L$2:$L$201,0)),"") -> Aarav Patel | D15: =IFERROR(INDEX('Raw Data'!$D$2:$D$201,MATCH(ROW()-4,'Raw Data'!$L$2:$L$201,0)),"") -> Excel Fundamentals | E15: =IFERROR(INDEX('Raw Data'!$E$2:$E$201,MATCH(ROW()-4,'Raw Data'!$L$2:$L$201,0)),"") -> B | F15: =IFERROR(INDEX('Raw Data'!$C$2:$C$201,MATCH(ROW()-4,'Raw Data'!$L$2:$L$201,0)),"") -> Waitlisted | G15: =IFERROR(INDEX('Raw Data'!$K$2:$K$201,MATCH(ROW()-4,'Raw Data'!$L$2:$L$201,0)),"") -> Resolve waitlist | H15: =IF($G15="","",IF(OR($G15="Follow up on absence",$G15="Resolve waitlist",$G15="Follow up - dropped participant"),"High","Medium")) -> High | I15: =IF($G15="","",IF($G15="Resolve waitlist","Program Coordinator","Learning Ops")) -> Program Coordinator | J15: =IFERROR(INDEX('Raw Data'!$G$2:$G$201,MATCH(ROW()-4,'Raw Data'!$L$2:$L$201,0))+7,"") -> 46156 | K15: =IF($G15="","","Open") -> Open
A16: ="ACT-"&TEXT(ROW()-4,"000") -> ACT-012 | B16: =IFERROR(INDEX('Raw Data'!$A$2:$A$201,MATCH(ROW()-4,'Raw Data'!$L$2:$L$201,0)),"") -> P022 | C16: =IFERROR(INDEX('Raw Data'!$B$2:$B$201,MATCH(ROW()-4,'Raw Data'!$L$2:$L$201,0)),"") -> Amit Mehta | D16: =IFERROR(INDEX('Raw Data'!$D$2:$D$201,MATCH(ROW()-4,'Raw Data'!$L$2:$L$201,0)),"") -> Data Analytics Basics | E16: =IFERROR(INDEX('Raw Data'!$E$2:$E$201,MATCH(ROW()-4,'Raw Data'!$L$2:$L$201,0)),"") -> A | F16: =IFERROR(INDEX('Raw Data'!$C$2:$C$201,MATCH(ROW()-4,'Raw Data'!$L$2:$L$201,0)),"") -> Registered | G16: =IFERROR(INDEX('Raw Data'!$K$2:$K$201,MATCH(ROW()-4,'Raw Data'!$L$2:$L$201,0)),"") -> Send completion certificate | H16: =IF($G16="","",IF(OR($G16="Follow up on absence",$G16="Resolve waitlist",$G16="Follow up - dropped participant"),"High","Medium")) -> Medium | I16: =IF($G16="","",IF($G16="Resolve waitlist","Program Coordinator","Learning Ops")) -> Learning Ops | J16: =IFERROR(INDEX('Raw Data'!$G$2:$G$201,MATCH(ROW()-4,'Raw Data'!$L$2:$L$201,0))+7,"") -> 46165 | K16: =IF($G16="","","Open") -> Open
... A105: ="ACT-"&TEXT(ROW()-4,"000") -> ACT-101 | B105: =IFERROR(INDEX('Raw Data'!$A$2:$A$201,MATCH(ROW()-4,'Raw Data'!$L$2:$L$201,0)),"") -> P200 | C105: =IFERROR(INDEX('Raw Data'!$B$2:$B$201,MATCH(ROW()-4,'Raw Data'!$L$2:$L$201,0)),"") -> Suresh Menon | D105: =IFERROR(INDEX('Raw Data'!$D$2:$D$201,MATCH(ROW()-4,'Raw Data'!$L$2:$L$201,0)),"") -> SQL for Beginners | E105: =IFERROR(INDEX('Raw Data'!$E$2:$E$201,MATCH(ROW()-4,'Raw Data'!$L$2:$L$201,0)),"") -> A | F105: =IFERROR(INDEX('Raw Data'!$C$2:$C$201,MATCH(ROW()-4,'Raw Data'!$L$2:$L$201,0)),"") -> Waitlisted | G105: =IFERROR(INDEX('Raw Data'!$K$2:$K$201,MATCH(ROW()-4,'Raw Data'!$L$2:$L$201,0)),"") -> Resolve waitlist | H105: =IF($G105="","",IF(OR($G105="Follow up on absence",$G105="Resolve waitlist",$G105="Follow up - dropped participant"),"High","Medium")) -> High | I105: =IF($G105="","",IF($G105="Resolve waitlist","Program Coordinator","Learning Ops")) -> Program Coordinator | J105: =IFERROR(INDEX('Raw Data'!$G$2:$G$201,MATCH(ROW()-4,'Raw Data'!$L$2:$L$201,0))+7,"") -> 46201 | K105: =IF($G105="","","Open") -> Open
